Workbook

Sheet BOM
A1: CC-BOM-01 · Kulübe İklim Kontrolörü · Malzeme Listesi · rev A · 28.10.2026
A2: Kaynak: docs/hardware/CC-BOM-01.md (CC-SCH-01 rev B + F2.4 WS2812B şeridi, src/app/pins.h). 230 V parçaların kurulumu ve enerjilendirmesi yetkili elektrikçi işidir.
A4: No | B4: Grup | C4: Ref. | D4: Parça / değer | E4: Kılıf / anma | F4: Görev / not | G4: Adet | H4: Birim | I4: Kapsam | J4: Sipariş kalemi
A5: 1 | B5: 1.1 Mantık kartı | C5: U1 | D5: Mean Well IRM-10-5 | E5: PCB modül, 5 V 2 A 10 W | F5: AC/DC besleme, çift izolasyonlu (Class II); girişi Sayfa 2 F1 sonrası | G5: 1 | H5: adet | I5: Zorunlu | J5: Mean Well IRM-10-5
A6: 2 | B6: 1.1 Mantık kartı | C6: U2 | D6: ESP32 DevKit V1 (DOIT, 30 pin) | E6: ESP32-WROOM-32, 4 MB flash, PSRAM yok | F6: MCU; kart üstü AMS1117 3.3 V, USB-UART, BOOT (GPIO0), mavi LED (GPIO2) | G6: 1 | H6: adet | I6: Zorunlu | J6: ESP32 DevKit V1 (DOIT, 30 pin)
A7: 3 | B7: 1.1 Mantık kartı | C7: U3 | D7: 2 kanal 5 V röle modülü | E7: Optokuplörlü, JD-VCC jumper'lı; SRD-05VDC-SL-C, kontak 10 A 250 VAC | F7: HF (IN1, GPIO32) ve VF (IN2, GPIO33), aktif-LOW. Jumper SÖKÜLÜ: VCC = 3.3 V, JD-VCC = 5 V | G7: 1 | H7: adet | I7: Zorunlu | J7: 2 kanal 5 V röle modülü
A8: 4 | B8: 1.1 Mantık kartı | C8: B1 | D8: DHT22 / AM2302 | E8: 3.3–5 V, tek hat | F8: T1 + RH1 sensörü, GPIO4 | G8: 1 | H8: adet | I8: Zorunlu | J8: DHT22 / AM2302
A9: 5 | B9: 1.1 Mantık kartı | C9: Q1, Q2 | D9: BC337-40 | E9: NPN, TO-92, 45 V 800 mA | F9: SSR1/SSR2 low-side sürücü | G9: 2 | H9: adet | I9: Zorunlu | J9: Transistör BC337-40
A10: 6 | B10: 1.1 Mantık kartı | C10: D1 | D10: SS34 | E10: Schottky 3 A 40 V, SMA | F10: USB bağlıyken U1'e geri beslemeyi engeller. Delikli kartta eşdeğer: 1N5822 | G10: 1 | H10: adet | I10: Zorunlu | J10: Diyot SS34 (veya 1N5822)
A11: 7 | B11: 1.1 Mantık kartı | C11: R1 | D11: 4.7 kΩ | E11: ¼ W %1 | F11: DHT22 DATA pull-up → 3.3 V | G11: 1 | H11: adet | I11: Zorunlu | J11: Direnç 4.7 kΩ ¼ W %1
A12: 8 | B12: 1.1 Mantık kartı | C12: R2 | D12: 100 Ω | E12: ¼ W | F12: DATA seri koruma | G12: 1 | H12: adet | I12: Zorunlu | J12: Direnç 100 Ω ¼ W
A13: 9 | B13: 1.1 Mantık kartı | C13: R3, R5 | D13: 1 kΩ | E13: ¼ W | F13: Q1/Q2 taban direnci | G13: 2 | H13: adet | I13: Zorunlu | J13: Direnç 1 kΩ ¼ W
A14: 10 | B14: 1.1 Mantık kartı | C14: R4, R6 | D14: 10 kΩ | E14: ¼ W | F14: Taban pull-down: reset/boot anında SSR kapalı | G14: 2 | H14: adet | I14: Zorunlu | J14: Direnç 10 kΩ ¼ W
A15: 11 | B15: 1.1 Mantık kartı | C15: R7, R8 | D15: 10 kΩ | E15: ¼ W | F15: Röle IN pull-up → 3.3 V: reset/boot anında röle bırakılmış | G15: 2 | H15: adet | I15: Zorunlu | J15: Direnç 10 kΩ ¼ W
A16: 12 | B16: 1.1 Mantık kartı | C16: C1 | D16: 470 µF 16 V | E16: Elektrolitik, 105 °C | F16: +5V tamponu (D1 çıkışı) | G16: 1 | H16: adet | I16: Zorunlu | J16: Kondansatör 470 µF 16 V elektrolitik
... A30: 26 | B30: 1.3 Kart montajı | C30: — | D30: Dişi pin header 1 × 15 | E30: 2.54 mm | F30: DevKit V1 soketi | G30: 2 | H30: adet | I30: Zorunlu | J30: Dişi pin header 1 × 15
A31: 27 | B31: 1.3 Kart montajı | C31: — | D31: M3 ara parça + vida/somun | F31: Kart montajı | G31: 4 | H31: takım | I31: Zorunlu | J31: M3 ara parça + vida/somun
A32: 28 | B32: 2 Şebeke tarafı | C32: X1 | D32: Giriş klemensi L / N / PE | E32: DIN ray, 2.5 mm²; PE yeşil-sarı | F32: Şebeke girişi (3 kutup) | G32: 1 | H32: takım | I32: Zorunlu | J32: Giriş klemensi L / N / PE
A33: 29 | B33: 2 Şebeke tarafı | C33: QF1 | D33: RCBO 1P+N C16, 30 mA, tip A | E33: DIN ray | F33: Ana aşırı akım + kaçak akım koruması; sonrası toplam ≈ 9.2 A | G33: 1 | H33: adet | I33: Zorunlu | J33: RCBO 1P+N C16, 30 mA, tip A
A34: 30 | B34: 2 Şebeke tarafı | C34: F1 | D34: Sigorta T 1 A 5×20 mm + DIN ray yuvası | E34: 250 V | F34: U1 beslemesi | G34: 1 | H34: adet | I34: Zorunlu | J34: Sigorta T 1 A 5×20 mm + DIN ray yuvası
A35: 31 | B35: 2 Şebeke tarafı | C35: F2 | D35: MCB 1P C10 | E35: DIN ray | F35: Rezistans dalı (2 × 4.35 A) | G35: 1 | H35: adet | I35: Zorunlu | J35: MCB 1P C10
A36: 32 | B36: 2 Şebeke tarafı | C36: F3 | D36: STB güvenlik termostatı | E36: Elle resetli, 16 A 250 VAC, ≈ 70 °C; kapiler hazneli veya elle resetli bimetal (KSD301 tipi, 16 A) | F36: Rezistans dalına seri, yazılımdan bağımsız; algılayıcı ısıtıcı çıkış havasında (CC-SCH-01 not 7) | G36: 1 | H36: adet | I36: Zorunlu | J36: STB güvenlik termostatı
A37: 33 | B37: 2 Şebeke tarafı | C37: F4 | D37: Sigorta T 2 A 5×20 mm + DIN ray yuvası | E37: 250 V | F37: Fan dalı | G37: 1 | H37: adet | I37: Zorunlu | J37: Sigorta T 2 A 5×20 mm + DIN ray yuvası
A38: 34 | B38: 2 Şebeke tarafı | C38: SSR1, SSR2 | D38: Sıfır geçişli SSR 25 A | E38: Giriş 3–32 VDC, çıkış ≥ 240 VAC; ör. Crydom D2425, Carlo Gavazzi RM1A23D25 | F38: R1/R2 rezistans anahtarı (SSR_ZC). Ucuz "SSR-25DA" kopyalarından kaçının: tipik arıza modu kısa devredir, ARM hattı yoktur | G38: 2 | H38: adet | I38: Zorunlu | J38: Sıfır geçişli SSR 25 A
A39: 35 | B39: 2 Şebeke tarafı | C39: — | D39: SSR soğutucusu | E39: Rth ≤ 3 K/W, termal macun veya ped ile | F39: SSR başına ≈ 5–6 W kayıp (4.35 A); rezistans hava akışının dışında | G39: 2 | H39: adet | I39: Zorunlu | J39: SSR soğutucusu
A40: 36 | B40: 2 Şebeke tarafı | C40: RV1, RV2 | D40: S14K275 varistör | E40: 275 VAC, 14 mm disk (TDK/EPCOS SIOV) | F40: SSR çıkışına paralel aşırı gerilim koruması | G40: 2 | H40: adet | I40: Zorunlu | J40: Varistör S14K275
A41: 37 | B41: 2 Şebeke tarafı | C41: R11, R12 | D41: 100 Ω | E41: 1 W, darbe dayanımlı | F41: Fan RC snubber direnci | G41: 2 | H41: adet | I41: Zorunlu | J41: Direnç 100 Ω 1 W
A42: 38 | B42: 2 Şebeke tarafı | C42: C6, C7 | D42: 100 nF X2 | E42: 275 VAC, MKP | F42: Fan RC snubber kondansatörü | G42: 2 | H42: adet | I42: Zorunlu | J42: Kondansatör 100 nF X2 275 VAC
A43: 39 | B43: 2 Şebeke tarafı | C43: E1, E2 | D43: Rezistans 1000 W 230 V | E43: Ör. kanatlı boru rezistans; metal gövde PE terminalli | F43: R1 / R2 ısıtıcı (4.35 A) | G43: 2 | H43: adet | I43: Zorunlu | J43: Rezistans 1000 W 230 V
... A46: 42 | B46: 3 Pano ve kurulum | C46: — | D46: Pano | E46: Metal, PE terminalli, en az IP54, DIN ray montaj plakalı; ör. 300 × 400 × 150 mm | F46: SSR soğutucuları ve mantık kartı için yer | G46: 1 | H46: adet | I46: Zorunlu | J46: Pano
A47: 43 | B47: 3 Pano ve kurulum | C47: — | D47: DIN ray TS35 | G47: 1 | H47: m | I47: Zorunlu | J47: DIN ray TS35
A48: 44 | B48: 3 Pano ve kurulum | C48: — | D48: PE barası | E48: ≥ 6 çıkış | F48: Pano, E1/E2 ve M1/M2 gövdeleri tek baraya yıldız bağlanır | G48: 1 | H48: adet | I48: Zorunlu | J48: PE barası
A49: 45 | B49: 3 Pano ve kurulum | C49: — | D49: Ray klemensi 2.5 mm² | E49: Geçiş (gri/mavi) ve PE (yeşil-sarı), köprü elemanlarıyla | F49: E1, E2, M1, M2 çıkışları (L/N/PE) ve N dağıtımı; ≈ 12–16, yerleşime göre | G49: 16 | H49: adet | I49: Zorunlu | J49: Ray klemensi 2.5 mm²
A50: 46 | B50: 3 Pano ve kurulum | C50: — | D50: Kablo rakoru M20 | F50: Şebeke, rezistans ve fan kabloları | G50: 5 | H50: adet | I50: Zorunlu | J50: Kablo rakoru M20
A51: 47 | B51: 3 Pano ve kurulum | C51: — | D51: Kablo rakoru M16 | F51: DHT22 kablosu | G51: 1 | H51: adet | I51: Zorunlu | J51: Kablo rakoru M16
A52: 48 | B52: 3 Pano ve kurulum | C52: — | D52: Kablo 1.5 mm² | E52: H05VV-F / H07V-K | F52: Giriş ve rezistans dalı (CC-SCH-01 not 5) | H52: m (g.k.) | I52: Zorunlu | J52: Kablo 1.5 mm²
A53: 49 | B53: 3 Pano ve kurulum | C53: — | D53: Kablo 0.75 mm² | F53: Fan dalı | H53: m (g.k.) | I53: Zorunlu | J53: Kablo 0.75 mm²
A54: 50 | B54: 3 Pano ve kurulum | C54: — | D54: Kablo 0.25–0.5 mm² | F54: SELV iç bağlantılar | H54: m (g.k.) | I54: Zorunlu | J54: Kablo 0.25–0.5 mm²
A55: 51 | B55: 3 Pano ve kurulum | C55: — | D55: Sensör kablosu, 4 damarlı ekranlı | F55: 3.3 V beslemede ≤ 5 m; daha uzunsa CC-SCH-01 not 3 | G55: 5 | H55: m | I55: Zorunlu | J55: Sensör kablosu, 4 damarlı ekranlı
A56: 52 | B56: 3 Pano ve kurulum | C56: — | D56: Kablo yüksüğü | E56: 0.5 / 0.75 / 1.5 / 2.5 mm² | G56: 1 | H56: takım | I56: Zorunlu | J56: Kablo yüksüğü
...

Sheet Sipariş listesi
A1: Sipariş listesi · aynı parçalar birleştirilmiş
A2: Üretim adedi Test satırlarını içermez. Sarı hücreler sizin dolduracağınız alanlardır (fiyat, tedarikçi, durum).
A4: No | B4: Sipariş kalemi | C4: Referanslar | D4: Birim | E4: Üretim adedi | F4: Test dahil | G4: Birim fiyat (₺) | H4: Tutar (₺) | I4: Tedarikçi | J4: Durum
A5: 1 | B5: Mean Well IRM-10-5 | C5: U1 | D5: adet | E5: =SUMIFS(BOM!$G$5:$G$63,BOM!$J$5:$J$63,B5,BOM!$I$5:$I$63,"<>Test") -> 1 | F5: =SUMIFS(BOM!$G$5:$G$63,BOM!$J$5:$J$63,B5) -> 1 | H5: =IF(G5="","",E5*G5) | J5: Bekliyor
A6: 2 | B6: ESP32 DevKit V1 (DOIT, 30 pin) | C6: U2 | D6: adet | E6: =SUMIFS(BOM!$G$5:$G$63,BOM!$J$5:$J$63,B6,BOM!$I$5:$I$63,"<>Test") -> 1 | F6: =SUMIFS(BOM!$G$5:$G$63,BOM!$J$5:$J$63,B6) -> 1 | H6: =IF(G6="","",E6*G6) | J6: Bekliyor
A7: 3 | B7: 2 kanal 5 V röle modülü | C7: U3 | D7: adet | E7: =SUMIFS(BOM!$G$5:$G$63,BOM!$J$5:$J$63,B7,BOM!$I$5:$I$63,"<>Test") -> 1 | F7: =SUMIFS(BOM!$G$5:$G$63,BOM!$J$5:$J$63,B7) -> 1 | H7: =IF(G7="","",E7*G7) | J7: Bekliyor
A8: 4 | B8: DHT22 / AM2302 | C8: B1 | D8: adet | E8: =SUMIFS(BOM!$G$5:$G$63,BOM!$J$5:$J$63,B8,BOM!$I$5:$I$63,"<>Test") -> 1 | F8: =SUMIFS(BOM!$G$5:$G$63,BOM!$J$5:$J$63,B8) -> 1 | H8: =IF(G8="","",E8*G8) | J8: Bekliyor
A9: 5 | B9: Transistör BC337-40 | C9: Q1, Q2 | D9: adet | E9: =SUMIFS(BOM!$G$5:$G$63,BOM!$J$5:$J$63,B9,BOM!$I$5:$I$63,"<>Test") -> 2 | F9: =SUMIFS(BOM!$G$5:$G$63,BOM!$J$5:$J$63,B9) -> 2 | H9: =IF(G9="","",E9*G9) | J9: Bekliyor
A10: 6 | B10: Diyot SS34 (veya 1N5822) | C10: D1 | D10: adet | E10: =SUMIFS(BOM!$G$5:$G$63,BOM!$J$5:$J$63,B10,BOM!$I$5:$I$63,"<>Test") -> 1 | F10: =SUMIFS(BOM!$G$5:$G$63,BOM!$J$5:$J$63,B10) -> 1 | H10: =IF(G10="","",E10*G10) | J10: Bekliyor
A11: 7 | B11: Direnç 4.7 kΩ ¼ W %1 | C11: R1 | D11: adet | E11: =SUMIFS(BOM!$G$5:$G$63,BOM!$J$5:$J$63,B11,BOM!$I$5:$I$63,"<>Test") -> 1 | F11: =SUMIFS(BOM!$G$5:$G$63,BOM!$J$5:$J$63,B11) -> 1 | H11: =IF(G11="","",E11*G11) | J11: Bekliyor
A12: 8 | B12: Direnç 100 Ω ¼ W | C12: R2 | D12: adet | E12: =SUMIFS(BOM!$G$5:$G$63,BOM!$J$5:$J$63,B12,BOM!$I$5:$I$63,"<>Test") -> 1 | F12: =SUMIFS(BOM!$G$5:$G$63,BOM!$J$5:$J$63,B12) -> 1 | H12: =IF(G12="","",E12*G12) | J12: Bekliyor
A13: 9 | B13: Direnç 1 kΩ ¼ W | C13: R3, R5, R9, R10 | D13: adet | E13: =SUMIFS(BOM!$G$5:$G$63,BOM!$J$5:$J$63,B13,BOM!$I$5:$I$63,"<>Test") -> 2 | F13: =SUMIFS(BOM!$G$5:$G$63,BOM!$J$5:$J$63,B13) -> 4 | H13: =IF(G13="","",E13*G13) | J13: Bekliyor
A14: 10 | B14: Direnç 10 kΩ ¼ W | C14: R4, R6, R7, R8 | D14: adet | E14: =SUMIFS(BOM!$G$5:$G$63,BOM!$J$5:$J$63,B14,BOM!$I$5:$I$63,"<>Test") -> 4 | F14: =SUMIFS(BOM!$G$5:$G$63,BOM!$J$5:$J$63,B14) -> 4 | H14: =IF(G14="","",E14*G14) | J14: Bekliyor
A15: 11 | B15: Kondansatör 470 µF 16 V elektrolitik | C15: C1, C8 | D15: adet | E15: =SUMIFS(BOM!$G$5:$G$63,BOM!$J$5:$J$63,B15,BOM!$I$5:$I$63,"<>Test") -> 2 | F15: =SUMIFS(BOM!$G$5:$G$63,BOM!$J$5:$J$63,B15) -> 2 | H15: =IF(G15="","",E15*G15) | J15: Bekliyor
A16: 12 | B16: Kondansatör 100 nF 50 V X7R | C16: C2, C4, C5, C9, C10 | D16: adet | E16: =SUMIFS(BOM!$G$5:$G$63,BOM!$J$5:$J$63,B16,BOM!$I$5:$I$63,"<>Test") -> 5 | F16: =SUMIFS(BOM!$G$5:$G$63,BOM!$J$5:$J$63,B16) -> 5 | H16: =IF(G16="","",E16*G16) | J16: Bekliyor
... A58: 54 | B58: Akkor / halojen lamba 25–60 W 230 V + duy | C58: — | D58: adet | E58: =SUMIFS(BOM!$G$5:$G$63,BOM!$J$5:$J$63,B58,BOM!$I$5:$I$63,"<>Test") -> 0 | F58: =SUMIFS(BOM!$G$5:$G$63,BOM!$J$5:$J$63,B58) -> 2 | H58: =IF(G58="","",E58*G58) | J58: Bekliyor
B59: Toplam (fiyatı girilen kalemler) | H59: =SUM(H5:H58) -> 0
B60: Fiyatı girilen kalem sayısı | H60: =COUNT(G5:G58)&" / "&COUNTA(B5:B58) -> 0 / 54
B62: Nasıl doldurulur
B63: Sarı hücreler (Birim fiyat, Tedarikçi, Durum) giriş alanıdır; diğerleri formül veya BOM sayfasından gelir.
B64: Birim fiyatı KDV dahil ₺ olarak yazın; Tutar = Üretim adedi × Birim fiyat. Örnek biçim (gerçek fiyat değil): 2,50 → Tutar 2 adet için 5,00.
B65: Tedarikçi serbest metindir (mağaza adı veya bağlantı). Durum listeden seçilir: Bekliyor · Sipariş verildi · Geldi · Stokta var.
B66: Kablo ve bariyer gibi "g.k." kalemlerin adedi boştur (–); uzunluk pano yerleşimine göre belirlenir.

Sheet Güç bütçesi
A1: +5V güç bütçesi · U1 Mean Well IRM-10-5
A2: Değerler datasheet tipik/üst değerlerinden alınmıştır; ölçülmemiştir. Mavi hücreler değiştirilebilir girişlerdir.
A4: Tüketici | B4: Adet | C4: Birim akım (mA) | D4: Toplam (mA) | E4: Kaynak / varsayım
A5: U2 ESP32 DevKit V1 (Wi-Fi gönderim tepesi, AMS1117 üzerinden) | B5: 1 | C5: 250 | D5: =B5*C5 -> 250 | E5: ESP32 datasheet: 802.11b gönderim ≈ 240 mA; yuvarlandı
A6: U3 röle bobini (SRD-05VDC) | B6: 2 | C6: 72 | D6: =B6*C6 -> 144 | E6: 5 V, 0.36 W bobin → ≈ 72 mA
A7: SSR girişi | B7: 2 | C7: 15 | D7: =B7*C7 -> 30 | E7: Üst sınır varsayımı (3–32 VDC girişli SSR, 5 V'ta)
A8: LS1 WS2812B LED (beyaz, %100 parlaklık) | B8: 6 | C8: 60 | D8: =B8*C8 -> 360 | E8: WS2812B: renk başına 20 mA × 3
A9: U3 opto, DHT22, pull-up dirençleri | B9: 1 | C9: 10 | D9: =B9*C9 -> 10 | E9: Tahmini toplam (opto 2 × ≈ 2 mA, DHT22 ≈ 1.5 mA)
A10: Toplam, en kötü durum (mA) | D10: =SUM(D5:D9) -> 794
A11: U1 anma akımı (mA) | D11: 2000 | E11: IRM-10-5: 5 V 2 A
A12: Kullanım oranı | D12: =D10/D11 -> 0.397
A13: WS2812B parlaklık ayarı | D13: 0.2 | E13: Firmware varsayılanı %20 (cc_ledstrip.h)
A14: Toplam, varsayılan parlaklıkta (mA) | D14: =D10-D8+D8*D13 -> 506
A15: U1 çıkış gerilimi (V) | D15: 5 | E15: IRM-10-5 nominal
A16: D1 SS34 ileri yön düşümü (V) | D16: 0.4 | E16: ≈ 0.8 A'de tipik
A17: +5V hattı (V) | D17: =D15-D16 -> 4.6
A18: AMS1117 3.3 V için yeterli mi (≥ 4.4 V) | D18: =IF(D17>=4.4,"Evet","HAYIR") -> Evet | E18: ≈ 1.1 V düşüm payı; HIL-1'de VIN yük altında ölçülmeli
A19: WS2812B besleme aralığında mı (3.5–5.3 V) | D19: =IF(AND(D17>=3.5,D17<=5.3),"Evet","HAYIR") -> Evet | E19: WS2812B datasheet
A20: Röle çeker mi (SRD-05VDC çekme ≤ 3.75 V) | D20: =IF(D17>=3.75,"Evet","HAYIR") -> Evet | E20: Bobin nominalinin %75'i

Sheet Notlar
A1: Notlar
A2: CC-BOM-01 rev A · 28.10.2026 · ayrıntı: docs/hardware/CC-BOM-01.md
B4: Şebeke gerilimi
B5: Şebeke tarafı (Grup 2 ve 3) kurulumu ve enerjilendirmesi yetkili elektrikçi tarafından yapılır. RCBO, STB ve PE bağlantıları ölçülmeden enerji verilmez (checklist 10). ARM hattı olmadığından SSR kısa devre arızasını yalnız F3 (STB) sınırlar.
B6: Çıkış sürücüleri
B7: Isıtıcılar (E1, E2) sıfır geçişli SSR ile sürülür: 20 s'lik zaman-oransal pencerede kanal başına saatte ≈ 180 anahtarlama yapılır; kontaklı röle bu yükte kısa sürede aşınır.
B8: Fanlar (M1, M2) U3 modülündeki kontaklı rölelerle sürülür: seyrek anahtarlanır (min. ON 60 s / OFF 30 s), kontak gerçek açık devre sağlar; RC snubber (R11/C6, R12/C7) kontak arkını ve EMI'yi sınırlar.
B9: Polarite: R1/R2 (GPIO25/26) aktif-HIGH, NPN low-side sürücü, tabanda pull-down. HF/VF (GPIO32/33) aktif-LOW, IN hattında pull-up. Farklı tetik polaritesinde bir SSR veya röle kartı seçilirse src/app/pins.h ve pull dirençleri değişir.
B10: LED'ler
B11: Sahada 6 adet WS2812B LED kullanılır (cc_ledstrip.h, kLedCount = 6). Kart üstü mavi LED (GPIO2) DevKit V1'in üzerindedir, ayrıca alınmaz. HIL LED1/LED2 yalnız ilk testte kullanılır.
B12: CC-SCH-01 rev B ile farklar
B13: 1. WS2812B şerit katı (LS1, U4, R13, C8–C10, J4) şemada çizili değil; F2.4'te pins.h'e eklendi (GPIO27). Referanslar bu listede önerilmiştir.
B14: 2. D1 (SS34) ve U4 (74AHCT1G125) yüzey montajlıdır; kart delikli pertinaksa 1N5822 ve 74HCT125N (veya 74AHCT125N) kullanılır; T'siz 74HC125 3.3 V girişi güvenilir okumaz.
B15: 3. Şema Sayfa 2 PE notundaki "U1 FG": IRM-10-5 Class II modüldür, FG pini yoktur.
... B18: HEATER_ARM hattı — GPIO13, lojik VE / ikinci transistör katı (OI-H6, ADR-008) · T2 hava çıkış sensörü — GPIO18 1-Wire, DS18B20 + 4.7 kΩ (OI-H2) · RTC — GPIO21/22 I²C, DS3231 (OI-H10; v1 NTP kullanır) · Fan geri bildirimi — akım trafosu veya RPM çıkışlı fan (OI-H7).
